<?xml version="1.0" ?>
<!-- =================================================================================== -->
<!-- |    This document was autogenerated by xacro from rccar.urdf.xacro               | -->
<!-- |    EDITING THIS FILE BY HAND IS NOT RECOMMENDED                                 | -->
<!-- =================================================================================== -->
<robot name="rccar">
  <material name="black">
    <color rgba="0.0 0.0 0.0 1.0"/>
  </material>
  <material name="dark">
    <color rgba="0.3 0.3 0.3 1.0"/>
  </material>
  <material name="light_black">
    <color rgba="0.4 0.4 0.4 1.0"/>
  </material>
  <material name="blue">
    <color rgba="0.0 0.0 0.8 1.0"/>
  </material>
  <material name="green">
    <color rgba="0.0 0.8 0.0 1.0"/>
  </material>
  <material name="grey">
    <color rgba="0.2 0.2 0.2 1.0"/>
  </material>
  <material name="darkgrey">
    <color rgba="0.3 0.3 0.3 1.0"/>
  </material>
  <material name="orange">
    <color rgba="1.0 0.4235294117647059 0.0392156862745098 1.0"/>
  </material>
  <material name="brown">
    <color rgba="0.8705882352941177 0.8117647058823529 0.7647058823529411 1.0"/>
  </material>
  <material name="red">
    <color rgba="0.8 0.0 0.0 1.0"/>
  </material>
  <material name="white">
    <color rgba="1.0 1.0 1.0 1.0"/>
  </material>
  <material name="aluminum">
    <color rgba="0.5 0.5 0.5 1"/>
  </material>
  <material name="plastic">
    <color rgba="0.1 0.1 0.1 1"/>
  </material>
  <gazebo reference="base_link">
    <material>Gazebo/Green</material>
  </gazebo>
  <gazebo reference="gps_link">
    <material>Gazebo/Black</material>
    <sensor name="ublox_gps" type="gps">
      <always_on>true</always_on>
      <update_rate>5.0</update_rate>
      <!--
      <gps>
        <position_sensing>
          <horizontal>
            <noise type="gaussian">
              <mean>0.0</mean>
              <stddev>1e-2</stddev>
            </noise>
          </horizontal>
          <vertical>
            <noise type="gaussian">
              <mean>0.0</mean>
              <stddev>1</stddev>
            </noise>
          </vertical>
        </position_sensing>
      </gps>
      -->
      <plugin filename="libgazebo_ros_gps_sensor.so" name="gazebo_ros_gps_sensor">
        <frame_name>gps_link</frame_name>
        <ros>
          <remapping>~/out:=/gnss/fix</remapping>
        </ros>
      </plugin>
    </sensor>
  </gazebo>
  <!--<gazebo reference="camera_imu_optical_frame">-->
  <gazebo reference="camera_gyro_optical_frame">
    <gravity>true</gravity>
    <sensor name="camera_imu" type="imu">
      <always_on>true</always_on>
      <update_rate>200</update_rate>
      <plugin filename="libgazebo_ros_imu_sensor.so" name="imu_plugin">
        <frame_name>camera_gyro_optical_frame</frame_name>
        <ros>
          <remapping>~/out:=/camera/imu_raw</remapping>
        </ros>
      </plugin>
    </sensor>
  </gazebo>
  <gazebo reference="camera_link">
    <sensor name="cameradepth" type="depth">
      <camera name="camera">
        <horizontal_fov>1.57</horizontal_fov>
        <image>
          <width>640</width>
          <height>480</height>
        </image>
        <clip>
          <near>0.1</near>
          <far>100</far>
        </clip>
        <noise>
          <type>gaussian</type>
          <mean>0.0</mean>
          <stddev>0.100</stddev>
        </noise>
      </camera>
      <always_on>1</always_on>
      <update_rate>30</update_rate>
      <visualize>0</visualize>
    </sensor>
    <sensor name="cameracolor" type="camera">
      <camera name="camera">
        <horizontal_fov>1.57</horizontal_fov>
        <image>
          <width>640</width>
          <height>480</height>
          <format>RGB_INT8</format>
        </image>
        <clip>
          <near>0.1</near>
          <far>100</far>
        </clip>
        <noise>
          <type>gaussian</type>
          <mean>0.0</mean>
          <stddev>0.007</stddev>
        </noise>
      </camera>
      <always_on>1</always_on>
      <update_rate>30</update_rate>
      <visualize>1</visualize>
    </sensor>
    <sensor name="cameraired1" type="camera">
      <camera name="camera">
        <horizontal_fov>1.57</horizontal_fov>
        <image>
          <width>640</width>
          <height>480</height>
          <format>L_INT8</format>
        </image>
        <clip>
          <near>0.1</near>
          <far>100</far>
        </clip>
        <noise>
          <type>gaussian</type>
          <mean>0.0</mean>
          <stddev>0.05</stddev>
        </noise>
      </camera>
      <always_on>1</always_on>
      <update_rate>1</update_rate>
      <visualize>0</visualize>
    </sensor>
    <sensor name="cameraired2" type="camera">
      <camera name="camera">
        <horizontal_fov>1.57</horizontal_fov>
        <image>
          <width>640</width>
          <height>480</height>
          <format>L_INT8</format>
        </image>
        <clip>
          <near>0.1</near>
          <far>100</far>
        </clip>
        <noise>
          <type>gaussian</type>
          <mean>0.0</mean>
          <stddev>0.05</stddev>
        </noise>
      </camera>
      <always_on>1</always_on>
      <update_rate>1</update_rate>
      <visualize>0</visualize>
    </sensor>
  </gazebo>
  <gazebo reference="realsense_joint">
    <disableFixedJointLumping>true</disableFixedJointLumping>
    <preserveFixedJoint>true</preserveFixedJoint>
  </gazebo>
  <gazebo>
    <plugin filename="librealsense_gazebo_plugin.so" name="gazebo_realsense">
      <prefix>camera</prefix>
      <depthUpdateRate>30.0</depthUpdateRate>
      <colorUpdateRate>30.0</colorUpdateRate>
      <infraredUpdateRate>1.0</infraredUpdateRate>
      <depthTopicName>camera/depth/image_rect_raw</depthTopicName>
      <depthCameraInfoTopicName>camera/depth/camera_info</depthCameraInfoTopicName>
      <colorTopicName>camera/color/image_raw</colorTopicName>
      <colorCameraInfoTopicName>camera/color/camera_info</colorCameraInfoTopicName>
      <infrared1TopicName>camera/infra1/image_raw</infrared1TopicName>
      <infrared1CameraInfoTopicName>camera/infra1/camera_info</infrared1CameraInfoTopicName>
      <infrared2TopicName>camera/infra2/image_raw</infrared2TopicName>
      <infrared2CameraInfoTopicName>camera/infra2/camera_info</infrared2CameraInfoTopicName>
      <colorOpticalframeName>camera_color_optical_frame</colorOpticalframeName>
      <depthOpticalframeName>camera_depth_optical_frame</depthOpticalframeName>
      <infrared1OpticalframeName>camera_left_ir_optical_frame</infrared1OpticalframeName>
      <infrared2OpticalframeName>camera_right_ir_optical_frame</infrared2OpticalframeName>
      <rangeMinDepth>0.3</rangeMinDepth>
      <rangeMaxDepth>3.0</rangeMaxDepth>
      <pointCloud>true</pointCloud>
      <pointCloudTopicName>camera/depth/color/points</pointCloudTopicName>
      <pointCloudCutoff>0.3</pointCloudCutoff>
    </plugin>
  </gazebo>
  <gazebo>
    <plugin filename="libgazebo_ros_ackermann_drive.so" name="gazebo_ros_ackermann_drive">
      <ros>
        <remapping>cmd_vel:=cmd_vel</remapping>
        <remapping>odom:=odometry/simulation</remapping>
        <remapping>distance:=distance</remapping>
      </ros>
      <!--<update_rate>33.3</update_rate>-->
      <!--<update_rate>10.0</update_rate>-->
      <update_rate>100.0</update_rate>
      <!-- wheels -->
      <front_left_joint>front_left_wheel_joint</front_left_joint>
      <front_right_joint>front_right_wheel_joint</front_right_joint>
      <rear_left_joint>rear_left_wheel_joint</rear_left_joint>
      <rear_right_joint>rear_right_wheel_joint</rear_right_joint>
      <left_steering_joint>front_left_mount_joint</left_steering_joint>
      <right_steering_joint>front_right_mount_joint</right_steering_joint>
      <!--<steering_wheel_joint>steering_joint</steering_wheel_joint>-->
      <!-- Max absolute steer angle for tyre in radians-->
      <!-- Any cmd_vel angular z greater than this would be capped -->
      <max_steer>0.6458</max_steer>
      <!-- Max absolute steering angle of steering wheel -->
      <max_steering_angle>7.85</max_steering_angle>
      <!-- Max absolute linear speed in m/s -->
      <max_speed>2.0</max_speed>
      <!-- PID tuning -->
      <left_steering_pid_gain>6 0 0</left_steering_pid_gain>
      <left_steering_i_range>0 0</left_steering_i_range>
      <right_steering_pid_gain>6 0 0</right_steering_pid_gain>
      <right_steering_i_range>0 0</right_steering_i_range>
      <linear_velocity_pid_gain>10 0 0</linear_velocity_pid_gain>
      <linear_velocity_i_range>0 0</linear_velocity_i_range>
      <!-- output -->
      <publish_odom>true</publish_odom>
      <publish_odom_tf>false</publish_odom_tf>
      <publish_wheel_tf>true</publish_wheel_tf>
      <publish_distance>true</publish_distance>
      <odometry_frame>odom</odometry_frame>
      <robot_base_frame>base_link</robot_base_frame>
    </plugin>
  </gazebo>
  <link name="base_link">
    <visual>
      <origin rpy="0 0 0" xyz="0.0 0.0 0.123"/>
      <geometry>
        <box size="0.385 0.195 0.057"/>
      </geometry>
      <material name="green"/>
    </visual>
    <visual>
      <origin rpy="0 0 0" xyz="0.0775 0.0 0.183"/>
      <geometry>
        <box size="0.110 0.195 0.063"/>
      </geometry>
      <material name="green"/>
    </visual>
    <collision>
      <origin rpy="0 0 0" xyz="-0.1925 -0.0975 0.0945"/>
      <geometry>
        <box size="0.385 0.195 0.120"/>
      </geometry>
    </collision>
    <inertial>
      <mass value="1.5"/>
      <inertia ixx="0.006553125" ixy="0" ixz="0" iyy="0.020328125" iyz="0" izz="0.02328125"/>
    </inertial>
  </link>
  <link name="gps_link">
    <visual>
      <origin rpy="0 0 0" xyz="0.0 0.0 0.0"/>
      <geometry>
        <box size="0.055 0.060 0.0225"/>
      </geometry>
      <material name="black"/>
    </visual>
  </link>
  <joint name="base_link_to_gps_link" type="fixed">
    <parent link="base_link"/>
    <child link="gps_link"/>
    <origin rpy="0 0 0" xyz="-0.1375 0.0 0.125"/>
  </joint>
  <!--
  <link name="camera_link">
    <visual>
      <origin xyz="0.0 0.0 0.0" rpy="0 0 0" />
      <geometry>
        <box size="0.025 0.090 0.025" />
      </geometry>
      <material name="white"/>
    </visual>
  </link>

  <joint name="base_link_to_camera_link" type="fixed">
    <parent link="base_link"/>
    <child link="camera_link" />
    <origin xyz="0.09615 0.0 0.185" rpy="0 0 0"/>
  </joint>
  -->
  <!-- camera body, with origin at bottom screw mount -->
  <joint name="camera_joint" type="fixed">
    <origin rpy="0 0 0" xyz="0.09615 0.0 0.185"/>
    <parent link="base_link"/>
    <child link="camera_bottom_screw_frame"/>
  </joint>
  <link name="camera_bottom_screw_frame"/>
  <joint name="camera_link_joint" type="fixed">
    <origin rpy="0 0 0" xyz="0.010600000000000002 0.0175 0.0125"/>
    <parent link="camera_bottom_screw_frame"/>
    <child link="camera_link"/>
  </joint>
  <link name="camera_link">
    <visual>
      <origin rpy="0 0 0" xyz="0 -0.0175 0"/>
      <geometry>
        <box size="0.02505 0.09 0.025"/>
      </geometry>
      <material name="aluminum"/>
    </visual>
    <collision>
      <origin rpy="0 0 0" xyz="0 -0.0175 0"/>
      <geometry>
        <box size="0.02505 0.09 0.025"/>
      </geometry>
    </collision>
    <inertial>
      <!-- The following are not reliable values, and should not be used for modeling -->
      <mass value="0.072"/>
      <origin xyz="0 0 0"/>
      <inertia ixx="0.003881243" ixy="0.0" ixz="0.0" iyy="0.000498940" iyz="0.0" izz="0.003879257"/>
    </inertial>
  </link>
  <!-- camera depth joints and links -->
  <joint name="camera_depth_joint" type="fixed">
    <origin rpy="0 0 0" xyz="0 0 0"/>
    <parent link="camera_link"/>
    <child link="camera_depth_frame"/>
  </joint>
  <link name="camera_depth_frame"/>
  <joint name="camera_depth_optical_joint" type="fixed">
    <origin rpy="-1.5707963267948966 0 -1.5707963267948966" xyz="0 0 0"/>
    <parent link="camera_depth_frame"/>
    <child link="camera_depth_optical_frame"/>
  </joint>
  <link name="camera_depth_optical_frame"/>
  <!-- camera left IR joints and links -->
  <joint name="camera_infra1_joint" type="fixed">
    <origin rpy="0 0 0" xyz="0 0.0 0"/>
    <parent link="camera_link"/>
    <child link="camera_infra1_frame"/>
  </joint>
  <link name="camera_infra1_frame"/>
  <joint name="camera_infra1_optical_joint" type="fixed">
    <origin rpy="-1.5707963267948966 0 -1.5707963267948966" xyz="0 0 0"/>
    <parent link="camera_infra1_frame"/>
    <child link="camera_infra1_optical_frame"/>
  </joint>
  <link name="camera_infra1_optical_frame"/>
  <!-- camera right IR joints and links -->
  <joint name="camera_infra2_joint" type="fixed">
    <origin rpy="0 0 0" xyz="0 -0.05 0"/>
    <parent link="camera_link"/>
    <child link="camera_infra2_frame"/>
  </joint>
  <link name="camera_infra2_frame"/>
  <joint name="camera_infra2_optical_joint" type="fixed">
    <origin rpy="-1.5707963267948966 0 -1.5707963267948966" xyz="0 0 0"/>
    <parent link="camera_infra2_frame"/>
    <child link="camera_infra2_optical_frame"/>
  </joint>
  <link name="camera_infra2_optical_frame"/>
  <!-- camera color joints and links -->
  <joint name="camera_color_joint" type="fixed">
    <origin rpy="0 0 0" xyz="0 0.015 0"/>
    <parent link="camera_link"/>
    <child link="camera_color_frame"/>
  </joint>
  <link name="camera_color_frame"/>
  <joint name="camera_color_optical_joint" type="fixed">
    <origin rpy="-1.5707963267948966 0 -1.5707963267948966" xyz="0 0 0"/>
    <parent link="camera_color_frame"/>
    <child link="camera_color_optical_frame"/>
  </joint>
  <link name="camera_color_optical_frame"/>
  <link name="camera_accel_frame"/>
  <link name="camera_accel_optical_frame"/>
  <link name="camera_gyro_frame"/>
  <link name="camera_gyro_optical_frame"/>
  <joint name="camera_accel_joint" type="fixed">
    <origin rpy="0 0 0" xyz="-0.01174 -0.00552 0.0051"/>
    <parent link="camera_link"/>
    <child link="camera_accel_frame"/>
  </joint>
  <joint name="camera_accel_optical_joint" type="fixed">
    <origin rpy="-1.5707963267948966 0 -1.5707963267948966" xyz="0 0 0"/>
    <parent link="camera_accel_frame"/>
    <child link="camera_accel_optical_frame"/>
  </joint>
  <joint name="camera_gyro_joint" type="fixed">
    <origin rpy="0 0 0" xyz="-0.01174 -0.00552 0.0051"/>
    <parent link="camera_link"/>
    <child link="camera_gyro_frame"/>
  </joint>
  <joint name="camera_gyro_optical_joint" type="fixed">
    <origin rpy="-1.5707963267948966 0 -1.5707963267948966" xyz="0 0 0"/>
    <parent link="camera_gyro_frame"/>
    <child link="camera_gyro_optical_frame"/>
  </joint>
  <link name="front_left_mount">
    <visual>
      <origin rpy="0 0 0" xyz="0.0 0.0 0.0"/>
      <geometry>
        <cylinder length="0.01" radius="0.045"/>
      </geometry>
      <material name="grey"/>
    </visual>
    <collision>
      <origin rpy="0 0 0" xyz="0.0 0.0 0.0"/>
      <geometry>
        <cylinder length="0.01" radius="0.045"/>
      </geometry>
    </collision>
    <inertial>
      <mass value="8.0"/>
      <inertia ixx="0.01" ixy="0.0" ixz="0.0" iyy="0.01" iyz="0.0" izz="0.01"/>
    </inertial>
  </link>
  <joint name="front_left_mount_joint" type="revolute">
    <parent link="base_link"/>
    <child link="front_left_mount"/>
    <axis rpy="0 0 0" xyz="0 0 1"/>
    <origin rpy="0 0 0" xyz="0.1215 0.08075 0.045"/>
    <!--<dynamics damping="0.0" friction="0.01" />-->
    <limit effort="4.2" lower="-0.6458" upper="0.6458" velocity="6.28"/>
    <!--<limit lower="-0.6458" upper="0.6458" effort="0.5" velocity="6.28" />-->
  </joint>
  <link name="front_left_wheel">
    <visual>
      <origin rpy="1.570796 0 0" xyz="0.0 0.0 0.0"/>
      <geometry>
        <cylinder length="0.0335" radius="0.045"/>
      </geometry>
      <material name="darkgrey"/>
    </visual>
    <collision>
      <origin rpy="1.570796 0 0" xyz="0.0 0.0 0.0"/>
      <geometry>
        <cylinder length="0.0335" radius="0.045"/>
      </geometry>
    </collision>
    <inertial>
      <mass value="0.5"/>
      <inertia ixx="0.01" ixy="0.0" ixz="0.0" iyy="0.01" iyz="0.0" izz="0.01"/>
    </inertial>
    <!--
      <inertial>
        <mass value="0.1" />
        <xacro:cylinder_inertia m="0.1" r="${wheel_diameter/2}" h="${wheel_thickness}" />
      </inertial>
      -->
  </link>
  <joint name="front_left_wheel_joint" type="continuous">
    <parent link="front_left_mount"/>
    <child link="front_left_wheel"/>
    <axis rpy="0 0 0" xyz="0 1 0"/>
    <origin rpy="0 0 0" xyz="0.0 0.0 0.0"/>
    <!--<dynamics damping="0.0" friction="0.01" />-->
  </joint>
  <gazebo reference="front_left_mount">
    <material>Gazebo/Grey</material>
  </gazebo>
  <gazebo reference="front_left_wheel">
    <material>Gazebo/DarkGrey</material>
  </gazebo>
  <link name="front_right_mount">
    <visual>
      <origin rpy="0 0 0" xyz="0.0 0.0 0.0"/>
      <geometry>
        <cylinder length="0.01" radius="0.045"/>
      </geometry>
      <material name="grey"/>
    </visual>
    <collision>
      <origin rpy="0 0 0" xyz="0.0 0.0 0.0"/>
      <geometry>
        <cylinder length="0.01" radius="0.045"/>
      </geometry>
    </collision>
    <inertial>
      <mass value="8.0"/>
      <inertia ixx="0.01" ixy="0.0" ixz="0.0" iyy="0.01" iyz="0.0" izz="0.01"/>
    </inertial>
  </link>
  <joint name="front_right_mount_joint" type="revolute">
    <parent link="base_link"/>
    <child link="front_right_mount"/>
    <axis rpy="0 0 0" xyz="0 0 1"/>
    <origin rpy="0 0 0" xyz="0.1215 -0.08075 0.045"/>
    <!--<dynamics damping="0.0" friction="0.01" />-->
    <limit effort="4.2" lower="-0.6458" upper="0.6458" velocity="6.28"/>
    <!--<limit lower="-0.6458" upper="0.6458" effort="0.5" velocity="6.28" />-->
  </joint>
  <link name="front_right_wheel">
    <visual>
      <origin rpy="1.570796 0 0" xyz="0.0 0.0 0.0"/>
      <geometry>
        <cylinder length="0.0335" radius="0.045"/>
      </geometry>
      <material name="darkgrey"/>
    </visual>
    <collision>
      <origin rpy="1.570796 0 0" xyz="0.0 0.0 0.0"/>
      <geometry>
        <cylinder length="0.0335" radius="0.045"/>
      </geometry>
    </collision>
    <inertial>
      <mass value="0.5"/>
      <inertia ixx="0.01" ixy="0.0" ixz="0.0" iyy="0.01" iyz="0.0" izz="0.01"/>
    </inertial>
    <!--
      <inertial>
        <mass value="0.1" />
        <xacro:cylinder_inertia m="0.1" r="${wheel_diameter/2}" h="${wheel_thickness}" />
      </inertial>
      -->
  </link>
  <joint name="front_right_wheel_joint" type="continuous">
    <parent link="front_right_mount"/>
    <child link="front_right_wheel"/>
    <axis rpy="0 0 0" xyz="0 1 0"/>
    <origin rpy="0 0 0" xyz="0.0 0.0 0.0"/>
    <!--<dynamics damping="0.0" friction="0.01" />-->
  </joint>
  <gazebo reference="front_right_mount">
    <material>Gazebo/Grey</material>
  </gazebo>
  <gazebo reference="front_right_wheel">
    <material>Gazebo/DarkGrey</material>
  </gazebo>
  <link name="rear_left_mount">
    <visual>
      <origin rpy="0 0 0" xyz="0.0 0.0 0.0"/>
      <geometry>
        <cylinder length="0.01" radius="0.045"/>
      </geometry>
      <material name="grey"/>
    </visual>
    <collision>
      <origin rpy="0 0 0" xyz="0.0 0.0 0.0"/>
      <geometry>
        <cylinder length="0.01" radius="0.045"/>
      </geometry>
    </collision>
    <inertial>
      <mass value="8.0"/>
      <inertia ixx="0.01" ixy="0.0" ixz="0.0" iyy="0.01" iyz="0.0" izz="0.01"/>
    </inertial>
  </link>
  <joint name="rear_left_mount_joint" type="fixed">
    <parent link="base_link"/>
    <child link="rear_left_mount"/>
    <axis rpy="0 0 0" xyz="0 0 1"/>
    <origin rpy="0 0 0" xyz="-0.1235 0.08075 0.045"/>
    <!--<dynamics damping="0.0" friction="0.01" />-->
    <limit effort="4.2" lower="-0.6458" upper="0.6458" velocity="6.28"/>
    <!--<limit lower="-0.6458" upper="0.6458" effort="0.5" velocity="6.28" />-->
  </joint>
  <link name="rear_left_wheel">
    <visual>
      <origin rpy="1.570796 0 0" xyz="0.0 0.0 0.0"/>
      <geometry>
        <cylinder length="0.0335" radius="0.045"/>
      </geometry>
      <material name="darkgrey"/>
    </visual>
    <collision>
      <origin rpy="1.570796 0 0" xyz="0.0 0.0 0.0"/>
      <geometry>
        <cylinder length="0.0335" radius="0.045"/>
      </geometry>
    </collision>
    <inertial>
      <mass value="0.5"/>
      <inertia ixx="0.01" ixy="0.0" ixz="0.0" iyy="0.01" iyz="0.0" izz="0.01"/>
    </inertial>
    <!--
      <inertial>
        <mass value="0.1" />
        <xacro:cylinder_inertia m="0.1" r="${wheel_diameter/2}" h="${wheel_thickness}" />
      </inertial>
      -->
  </link>
  <joint name="rear_left_wheel_joint" type="continuous">
    <parent link="rear_left_mount"/>
    <child link="rear_left_wheel"/>
    <axis rpy="0 0 0" xyz="0 1 0"/>
    <origin rpy="0 0 0" xyz="0.0 0.0 0.0"/>
    <!--<dynamics damping="0.0" friction="0.01" />-->
  </joint>
  <gazebo reference="rear_left_mount">
    <material>Gazebo/Grey</material>
  </gazebo>
  <gazebo reference="rear_left_wheel">
    <material>Gazebo/DarkGrey</material>
  </gazebo>
  <link name="rear_right_mount">
    <visual>
      <origin rpy="0 0 0" xyz="0.0 0.0 0.0"/>
      <geometry>
        <cylinder length="0.01" radius="0.045"/>
      </geometry>
      <material name="grey"/>
    </visual>
    <collision>
      <origin rpy="0 0 0" xyz="0.0 0.0 0.0"/>
      <geometry>
        <cylinder length="0.01" radius="0.045"/>
      </geometry>
    </collision>
    <inertial>
      <mass value="8.0"/>
      <inertia ixx="0.01" ixy="0.0" ixz="0.0" iyy="0.01" iyz="0.0" izz="0.01"/>
    </inertial>
  </link>
  <joint name="rear_right_mount_joint" type="fixed">
    <parent link="base_link"/>
    <child link="rear_right_mount"/>
    <axis rpy="0 0 0" xyz="0 0 1"/>
    <origin rpy="0 0 0" xyz="-0.1235 -0.08075 0.045"/>
    <!--<dynamics damping="0.0" friction="0.01" />-->
    <limit effort="4.2" lower="-0.6458" upper="0.6458" velocity="6.28"/>
    <!--<limit lower="-0.6458" upper="0.6458" effort="0.5" velocity="6.28" />-->
  </joint>
  <link name="rear_right_wheel">
    <visual>
      <origin rpy="1.570796 0 0" xyz="0.0 0.0 0.0"/>
      <geometry>
        <cylinder length="0.0335" radius="0.045"/>
      </geometry>
      <material name="darkgrey"/>
    </visual>
    <collision>
      <origin rpy="1.570796 0 0" xyz="0.0 0.0 0.0"/>
      <geometry>
        <cylinder length="0.0335" radius="0.045"/>
      </geometry>
    </collision>
    <inertial>
      <mass value="0.5"/>
      <inertia ixx="0.01" ixy="0.0" ixz="0.0" iyy="0.01" iyz="0.0" izz="0.01"/>
    </inertial>
    <!--
      <inertial>
        <mass value="0.1" />
        <xacro:cylinder_inertia m="0.1" r="${wheel_diameter/2}" h="${wheel_thickness}" />
      </inertial>
      -->
  </link>
  <joint name="rear_right_wheel_joint" type="continuous">
    <parent link="rear_right_mount"/>
    <child link="rear_right_wheel"/>
    <axis rpy="0 0 0" xyz="0 1 0"/>
    <origin rpy="0 0 0" xyz="0.0 0.0 0.0"/>
    <!--<dynamics damping="0.0" friction="0.01" />-->
  </joint>
  <gazebo reference="rear_right_mount">
    <material>Gazebo/Grey</material>
  </gazebo>
  <gazebo reference="rear_right_wheel">
    <material>Gazebo/DarkGrey</material>
  </gazebo>
</robot>
